#VRML_SIM R2019a utf8
WorldInfo {
}
Viewpoint {
  orientation -0.6884022784956838 0.6946520532964855 0.20871230872406113 0.8230642352988621
  position 2.5648310134027175 3.8414731123055086 3.2922161446878766
}
TexturedBackground {
}
TexturedBackgroundLight {
}
Floor {
}
DEF BASE Solid {
  translation 0 0.025 0
  children [
    DEF G_BASE Group {
      children [
        Shape {
          appearance DEF T_GREEN PBRAppearance {
            baseColor 0.5411764705882353 0.8862745098039215 0.20392156862745098
            metalness 0
          }
          geometry Box {
            size 1 0.05 1
          }
        }
      ]
    }
  ]
}
DEF FACE_RED Solid {
  translation 0.005 0.1 0.495
  children [
    DEF G_FACE Group {
      children [
        Shape {
          appearance DEF F_RED PBRAppearance {
            baseColor 0.9372549019607843 0.1607843137254902 0.1607843137254902
            metalness 0
          }
          geometry DEF B_BAR Box {
            size 0.99 0.1 0.01
          }
        }
        Transform {
          translation 0.445 0.4 0
          children [
            Shape {
              appearance USE F_RED
              geometry DEF L_BAR Box {
                size 0.1 0.7 0.01
              }
            }
          ]
        }
        Transform {
          translation -0.445 0.4 0
          children [
            Shape {
              appearance USE F_RED
              geometry USE L_BAR
            }
          ]
        }
        Transform {
          translation 0 0.8 0
          children [
            Shape {
              appearance USE F_RED
              geometry USE B_BAR
            }
          ]
        }
        Transform {
          translation 0 0.4 0
          rotation 0 0 1 0.85
          children [
            Shape {
              appearance USE F_RED
              geometry DEF D_BAR Box {
                size 0.07 1.2 0.01
              }
            }
          ]
        }
        Transform {
          translation 0 0.4 0
          rotation 0 0 1 -0.85
          children [
            Shape {
              appearance USE F_RED
              geometry USE D_BAR
            }
          ]
        }
      ]
    }
  ]
  name "solid(1)"
}
DEF FACE_RED2 Solid {
  translation -0.005 0.1 -0.495
  children [
    USE G_FACE
  ]
  name "solid(2)"
}
DEF FACE_BLUE Solid {
  translation 0.495 0.1 -0.005
  rotation 0 1 0 1.5707996938995747
  children [
    DEF G_FACE2 Group {
      children [
        Shape {
          appearance DEF F_BLUE PBRAppearance {
            baseColor 0.20392156862745098 0.396078431372549 0.6431372549019608
            metalness 0
          }
          geometry DEF B_BAR Box {
            size 0.99 0.1 0.01
          }
        }
        Transform {
          translation 0.445 0.4 0
          children [
            Shape {
              appearance USE F_BLUE
              geometry DEF L_BAR Box {
                size 0.1 0.7 0.01
              }
            }
          ]
        }
        Transform {
          translation -0.445 0.4 0
          children [
            Shape {
              appearance USE F_BLUE
              geometry USE L_BAR
            }
          ]
        }
        Transform {
          translation 0 0.8 0
          children [
            Shape {
              appearance USE F_BLUE
              geometry USE B_BAR
            }
          ]
        }
        Transform {
          translation 0 0.4 0
          rotation 0 0 1 0.85
          children [
            Shape {
              appearance USE F_BLUE
              geometry DEF D_BAR Box {
                size 0.07 1.2 0.01
              }
            }
          ]
        }
        Transform {
          translation 0 0.4 0
          rotation 0 0 1 -0.85
          children [
            Shape {
              appearance USE F_BLUE
              geometry USE D_BAR
            }
          ]
        }
      ]
    }
  ]
  name "solid(3)"
}
DEF FACE_BLUE2 Solid {
  translation -0.495 0.1 0.005
  rotation 0 1 0 1.5707996938995747
  children [
    USE G_FACE2
  ]
  name "solid(4)"
}
DEF BASE2 Solid {
  translation 0 0.975 0
  children [
    USE G_BASE
  ]
  name "solid(5)"
}
DEF MILL Solid {
  children [
    Solid {
      translation 0 1.4 0
      children [
        Shape {
          appearance PBRAppearance {
            baseColor 0.5333333333333333 0.5411764705882353 0.5215686274509804
          }
          geometry Cylinder {
            height 0.8
            radius 0.05
          }
        }
        HingeJoint {
          jointParameters HingeJointParameters {
            position -25.429698574224073
            axis 0 1 0
            anchor 0 0.4 0
            staticFriction 0.02
          }
          endPoint Solid {
            translation 0.09562312314951321 0.45 0.029261208435965736
            rotation -0.1463411002255039 -0.14634060748053032 0.9783499930939942 1.5926857524650648
            children [
              Shape {
                appearance PBRAppearance {
                  baseColor 0.7568627450980392 0.49019607843137253 0.06666666666666667
                  metalness 0
                }
                geometry DEF CYL Cylinder {
                  height 0.4
                  radius 0.05
                }
              }
              HingeJoint {
                jointParameters HingeJointParameters {
                  position 18.33259216274445
                  axis 0 1 0
                  anchor 0 -0.2 0
                  staticFriction 0.01
                }
                endPoint Solid {
                  translation 0 -0.205 0
                  rotation 0 1 0 5.7662215483852775
                  children [
                    DEF HEL Group {
                      children [
                        Shape {
                          appearance DEF H_P PBRAppearance {
                            baseColor 0.4588235294117647 0.3137254901960784 0.4823529411764706
                            metalness 0
                          }
                          geometry DEF H_BOX Box {
                            size 0.6 0.01 0.1
                          }
                        }
                        Transform {
                          rotation 0 1 0 1.5708003061004252
                          children [
                            Shape {
                              appearance USE H_P
                              geometry USE H_BOX
                            }
                          ]
                        }
                      ]
                    }
                  ]
                  boundingObject USE HEL
                  physics Physics {
                  }
                }
              }
            ]
            boundingObject USE CYL
            physics Physics {
            }
          }
        }
      ]
    }
  ]
  name "solid(6)"
}
DEF CUBE_1_1_1_W_TRANSP Solid {
  translation 0 0.5 0
  children [
    Shape {
      appearance PBRAppearance {
        transparency 1
      }
      geometry Box {
        size 1 1 1
      }
    }
  ]
  name "solid(7)"
}
